Exception ignored in: <function Person.__del__ at 0x000001C61ECC9DC0>
Traceback (most recent call last):
  File "C:\OOP\polymorphism\07.py", line 141, in __del__
    raise ValueError('Something went bad...')
ValueError: Something went bad...
